# 抛出异常

## 异常的传播

​	当方法抛出了异常时，如果当前方法没有捕获异常，异常就会被抛到上层调用方法，直到遇到某个`try ... catch`被捕获为止

​	通过`printStackTrace()`可以打印出方法的调用栈，类似：

```java
java.lang.NumberFormatException: null
    at java.base/java.lang.Integer.parseInt(Integer.java:614)
    at java.base/java.lang.Integer.parseInt(Integer.java:770)
    at Main.process2(Main.java:16)
    at Main.process1(Main.java:12)
    at Main.main(Main.java:5)
```

​	每层调用均给出了源代码的行号，可直接进行定位。



## 抛出异常

​	当发生错误时，例如，用户输入了非法的字符，可以抛出异常。

​	抛出异常通常是创建了某个Exception实例，用throw将其抛出。一般融合成一句。

```java
throw new NullPointerException();
```

​	



​	如果在调用的过程中，一个方法捕获了某个异常，又在catch中抛出了新的异常。相当于把抛出异常的类型转换了。

```java
void process1(String s) {
    try {
        process2();
    } catch (NullPointerException e) {
        throw new IllegalArgumentException();
    }
}

void process2(String s) {
    if (s==null) {
        throw new NullPointerException();
    }
}
```

​	此时如果我们在main()捕获IllegalArgumentException，就会发现无法溯源了

```java
// exception
public class Main {
    public static void main(String[] args) {
        try {
            process1();
        } catch (Exception e) {
            e.printStackTrace();
        }
    }

    static void process1() {
        try {
            process2();
        } catch (NullPointerException e) {
            throw new IllegalArgumentException();
        }
    }

    static void process2() {
        throw new NullPointerException();
    }
}
```

```plain
java.lang.IllegalArgumentException
    at Main.process1(Main.java:15)
    at Main.main(Main.java:5)
```

​	说明新的异常丢失了原始异常信息，我们看不到原本的NullPointerException了。



​	为了能追踪到完整的异常栈，在构造的时候，把原始的Exception实例传进去，新的Exception就可以持有Exception信息

```plain
java.lang.IllegalArgumentException: java.lang.NullPointerException
    at Main.process1(Main.java:15)
    at Main.main(Main.java:5)
Caused by: java.lang.NullPointerException
    at Main.process2(Main.java:20)
    at Main.process1(Main.java:13)
```

​	可以发现多了Caused by，说明捕获的IllegalArgumentException不是问题的根源，根源是NullPointerException。



​	在代码中获取原始异常可以使用`Throwable.getCause()`方法。如果返回`null`，说明已经是“根异常”了。



​	finally执行不受异常影响。





## 异常屏蔽

​	如果在执行finally语句时抛出异常，那么